Workbook
Name L_Type: OFFSET(Lists!$A$5,0,0,MAX(1,COUNTA(Lists!$A$5:$A$60)),1)
Name L_Region: OFFSET(Lists!$B$5,0,0,MAX(1,COUNTA(Lists!$B$5:$B$60)),1)
Name L_Situation: OFFSET(Lists!$C$5,0,0,MAX(1,COUNTA(Lists!$C$5:$C$60)),1)
Name L_YNU: OFFSET(Lists!$D$5,0,0,MAX(1,COUNTA(Lists!$D$5:$D$60)),1)
Name L_Service: OFFSET(Lists!$E$5,0,0,MAX(1,COUNTA(Lists!$E$5:$E$60)),1)
Name L_Need: OFFSET(Lists!$F$5,0,0,MAX(1,COUNTA(Lists!$F$5:$F$60)),1)
Name L_Stage: OFFSET(Lists!$G$5,0,0,MAX(1,COUNTA(Lists!$G$5:$G$60)),1)
Name L_Tick: OFFSET(Lists!$H$5,0,0,MAX(1,COUNTA(Lists!$H$5:$H$60)),1)
Name L_YesNo: OFFSET(Lists!$I$5,0,0,MAX(1,COUNTA(Lists!$I$5:$I$60)),1)
Name L_EventType: OFFSET(Lists!$J$5,0,0,MAX(1,COUNTA(Lists!$J$5:$J$60)),1)
Name f_Id: Setup!$D$6
Name f_Time: Setup!$D$7
Name f_Name: Setup!$D$8
Name f_Email: Setup!$D$9
Name f_Phone: Setup!$D$10
Name f_City: Setup!$D$11
Name f_Who: Setup!$D$12
Name f_Org1: Setup!$D$13
Name f_Org2: Setup!$D$14
Name f_Region: Setup!$D$15
Name f_Sit: Setup!$D$16
Name f_Appr: Setup!$D$17
Name f_Trade: Setup!$D$18
Name f_SelfID: Setup!$D$19
Name f_Need: Setup!$D$20
Name f_Consent: Setup!$D$21
Name f_Event: Setup!$D$22
Name FormData: Sheet1!$A$1:$AZ$5000
Name FormHdr: Sheet1!$A$1:$AZ$1
Name DueSoon: Setup!$C$26
Name WhoKW: Setup!$B$46:$B$67
Name WhoVal: Setup!$C$46:$C$67
Name SitKW: Setup!$E$46:$E$67
Name SitVal: Setup!$F$46:$F$67
Name EvID: Events!$A$5:$A$104
Name EvDate: Events!$B$5:$B$104
Name EvName: Events!$C$5:$C$104

Sheet Start Here
B1: BOOST Ontario — Participant Tracker
B2: Literacy Link South Central · Version 4 · October 2026
B5: THE IDEA
B6: Private by design | C6: People are tracked by Participant # and initials. Names, emails and phone numbers stay in the Microsoft Forms response sheet and only appear on Contact Card, one person at a time.
B7: One number links it | C7: Type the form's Response ID on a People row. Event, date, initials, type, region and consent fill themselves.
B8: Notes are the point | C8: Contact details can always be looked up again. What someone told you at the table can't — that's what Conversation Notes is for.
B10: BEFORE THE EVENT
B11: 1. Events | C11: Add a row: Event ID (EV-013, EV-014 …) and the DATE. Sign-ups find their event by the date, so the date matters most.
B13: AT THE TABLE
B14: 2. They scan the QR | C14: The form does the capturing. Nothing to type in the tracker yet.
B15: Walk-ups | C15: No form? Add a People row: type the date in Registered On, their initials, and the Contact Type. The Event ID fills from the date.
B17: AFTER THE EVENT
B18: 3. New Sign-Ups | C18: Shows everyone who filled in the form. Anyone marked → add isn't on People yet.
B19: 4. People | C19: For each one, type the Response ID in column U on the next empty row. Then add Service Level, Main Need, Stage and your notes.
B20: 5. Follow-Ups | C20: Tick Follow-Up Needed and give it a due date. Follow-Ups lists everyone you owe a call, soonest first. Enter the date in Follow-Up Done when it's done.
B21: 6. Event Report | C21: Pick the Event ID, write your note to the reader, then File → Print → Save as PDF. It shows initials only, so it's safe to send.
B23: WHEN YOU NEED TO CALL
B24: Contact Card | C24: Type the Participant #. Name, email and phone appear. Clear the box afterwards. Never screen-share this tab.
B26: COLOURS
B27: Header colours | C27: Teal = fills itself from the form, but you can type over it. Navy = yours. Grey = counts itself. Orange = the link (Form Response ID).
B28: Cell colours | C28: Yellow = type here. Red on Event ID = no event matched that date. Amber on Event ID = two events on the same day, so check it. Light grey = doesn't apply to this contact type.
B30: PRIVACY RULES
B31: In notes | C31: Write what they need and what you agreed, not who they are. No health details, diagnoses, SIN, dates of birth or addresses.
B32: Self-identification | C32: Never typed into the tracker. The Dashboard counts it straight from the form as totals only.
B33: Consent = No | C33: Shows in red on People and Contact Card. Don't contact them.
B34: Sharing | C34: People, Events, Follow-Ups, Event Report and Dashboard hold no contact details. Contact Card and Sheet1 do.
B36: CONNECTING THE FORM
B37: Where responses live | C37: Microsoft Forms writes responses to “Event Registration - Literacy Link South Central.xlsx” (OneDrive → Documents), on a sheet called Sheet1.
B38: Option A — paste (simplest) | C38: In Forms: Responses → Open in Excel. Select all on that sheet, copy, and paste over this file's Sheet1 at A1. Takes 30 seconds after each event.
B39: Option B — live | C39: Copy every tab EXCEPT Sheet1 into the Forms workbook (right-click a tab → Move or Copy → tick Create a copy; do Lists and Setup first). Then Data → Edit Links → Change Source → choose the Forms workbook itself, so the formulas point at its real Sheet1.
B40: Setup tab | C40: If a heading on the form is worded differently, Setup will show ✗. Type a word from the real heading into the yellow cell and it reconnects.
B42: DON'T
B43: … | C43: Don't delete or rename Sheet1. Don't delete rows on People — clear them instead (Participant #s must stay unique). Don't unhide and edit the grey helper columns (W–Z on People).

Sheet People
A1: People
A2: One row per person you speak with. Initials and a number only — names, emails and phones stay in the form.
A3: ◀ ID | B3: AUTO — fills from the form once you type the Form Response ID (col U). Type over any of these to change that row. | K3: YOURS — the conversation | U3: LINK
A4: Participant # | B4: Event ID | C4: Registered On | D4: Initials | E4: Contact Type | F4: Organization | G4: Region | H4: Situation | I4: Reg. Apprentice | J4: Trade | K4: Service Level | L4: Main Need | M4: Stage | N4: Conversation Notes | O4: Materials Given | P4: Follow-Up Needed | Q4: Follow-Up Due | R4: Follow-Up Done | S4: Follow-Up Status | T4: Consent | U4: Form Response ID | V4: Form Check | W4: _form row | X4: _report | Y4: _follow-up | Z4: _in use
A5: P-0001 | B5: =IF(AND($U5="",$C5=""),"",IFERROR(INDEX(EvID,MATCH(INDEX(FormData,$W5,f_Event),EvID,0)),IFERROR(INDEX(EvID,MATCH(INDEX(FormData,$W5,f_Event),EvName,0)),IFERROR(INDEX(EvID,MATCH(INT($C5),EvDate,0)),"")))) | C5: =IF($W5="","",INDEX(FormData,$W5,f_Time)) | D5: =IF($W5="","",IFERROR(UPPER(LEFT(TRIM(INDEX(FormData,$W5,f_Name)),1)&IFERROR(MID(TRIM(INDEX(FormData,$W5,f_Name)),FIND("^",SUBSTITUTE(TRIM(INDEX(FormData,$W5,f_Name))," ","^",LEN(TRIM(INDEX(FormData,$W5,f_Name)))-LEN(SUBSTITUTE(TRIM(INDEX(FormData,$W5,f_Name))," ",""))))+1,1),"")),"")) | E5: =IF($W5="","",IFERROR(IF(SUMPRODUCT(MAX((WhoKW<>"")*ISNUMBER(SEARCH(WhoKW,INDEX(FormData,$W5,f_Who)&""))*(ROW(WhoKW)-MIN(ROW(WhoKW))+1)))=0,"",INDEX(WhoVal,SUMPRODUCT(MAX((WhoKW<>"")*ISNUMBER(SEARCH(WhoKW,INDEX(FormData,$W5,f_Who)&""))*(ROW(WhoKW)-MIN(ROW(WhoKW))+1))))),"")) | F5: =IF($W5="","",TRIM(IFERROR(INDEX(FormData,$W5,f_Org1)&"","")&" "&IFERROR(INDEX(FormData,$W5,f_Org2)&"",""))) | G5: =IF($W5="","",IFERROR(INDEX(FormData,$W5,f_Region)&"","")) | H5: =IF($W5="","",IFERROR(IF(SUMPRODUCT(MAX((SitKW<>"")*ISNUMBER(SEARCH(SitKW,INDEX(FormData,$W5,f_Sit)&""))*(ROW(SitKW)-MIN(ROW(SitKW))+1)))=0,"",INDEX(SitVal,SUMPRODUCT(MAX((SitKW<>"")*ISNUMBER(SEARCH(SitKW,INDEX(FormData,$W5,f_Sit)&""))*(ROW(SitKW)-MIN(ROW(SitKW))+1))))),"")) | I5: =IF($W5="","",IFERROR(INDEX(FormData,$W5,f_Appr)&"","")) | J5: =IF($W5="","",IFERROR(INDEX(FormData,$W5,f_Trade)&"","")) | S5: =IF($P5<>"✓","",IF($R5<>"","Done",IF($Q5="","Open — no date",IF($Q5<TODAY(),"Overdue",IF($Q5-TODAY()<=DueSoon,"Due soon","Scheduled"))))) | T5: =IF($W5="","",IFERROR(IF(INDEX(FormData,$W5,f_Consent)&""="","",IF(ISNUMBER(SEARCH("yes",INDEX(FormData,$W5,f_Consent))),"Yes","No")),"")) | V5: =IF($U5="","",IF($W5="","not found","✓")) | W5: =IF($U5="","",IFERROR(MATCH($U5,INDEX(FormData,0,f_Id),0),IFERROR(MATCH(--$U5,INDEX(FormData,0,f_Id),0),IFERROR(MATCH($U5&"",INDEX(FormData,0,f_Id),0),"")))) | X5: =IF(AND($B5<>"",$B5='Event Report'!$C$3),ROW(),"") | Y5: =IF(AND($P5="✓",$R5=""),IF($Q5="",90000,$Q5)+ROW()/100000,"") | Z5: =IF(OR($U5<>"",$D5<>"",$E5<>"",$N5<>""),1,"")
A6: P-0002 | B6: =IF(AND($U6="",$C6=""),"",IFERROR(INDEX(EvID,MATCH(INDEX(FormData,$W6,f_Event),EvID,0)),IFERROR(INDEX(EvID,MATCH(INDEX(FormData,$W6,f_Event),EvName,0)),IFERROR(INDEX(EvID,MATCH(INT($C6),EvDate,0)),"")))) | C6: =IF($W6="","",INDEX(FormData,$W6,f_Time)) | D6: =IF($W6="","",IFERROR(UPPER(LEFT(TRIM(INDEX(FormData,$W6,f_Name)),1)&IFERROR(MID(TRIM(INDEX(FormData,$W6,f_Name)),FIND("^",SUBSTITUTE(TRIM(INDEX(FormData,$W6,f_Name))," ","^",LEN(TRIM(INDEX(FormData,$W6,f_Name)))-LEN(SUBSTITUTE(TRIM(INDEX(FormData,$W6,f_Name))," ",""))))+1,1),"")),"")) | E6: =IF($W6="","",IFERROR(IF(SUMPRODUCT(MAX((WhoKW<>"")*ISNUMBER(SEARCH(WhoKW,INDEX(FormData,$W6,f_Who)&""))*(ROW(WhoKW)-MIN(ROW(WhoKW))+1)))=0,"",INDEX(WhoVal,SUMPRODUCT(MAX((WhoKW<>"")*ISNUMBER(SEARCH(WhoKW,INDEX(FormData,$W6,f_Who)&""))*(ROW(WhoKW)-MIN(ROW(WhoKW))+1))))),"")) | F6: =IF($W6="","",TRIM(IFERROR(INDEX(FormData,$W6,f_Org1)&"","")&" "&IFERROR(INDEX(FormData,$W6,f_Org2)&"",""))) | G6: =IF($W6="","",IFERROR(INDEX(FormData,$W6,f_Region)&"","")) | H6: =IF($W6="","",IFERROR(IF(SUMPRODUCT(MAX((SitKW<>"")*ISNUMBER(SEARCH(SitKW,INDEX(FormData,$W6,f_Sit)&""))*(ROW(SitKW)-MIN(ROW(SitKW))+1)))=0,"",INDEX(SitVal,SUMPRODUCT(MAX((SitKW<>"")*ISNUMBER(SEARCH(SitKW,INDEX(FormData,$W6,f_Sit)&""))*(ROW(SitKW)-MIN(ROW(SitKW))+1))))),"")) | I6: =IF($W6="","",IFERROR(INDEX(FormData,$W6,f_Appr)&"","")) | J6: =IF($W6="","",IFERROR(INDEX(FormData,$W6,f_Trade)&"","")) | S6: =IF($P6<>"✓","",IF($R6<>"","Done",IF($Q6="","Open — no date",IF($Q6<TODAY(),"Overdue",IF($Q6-TODAY()<=DueSoon,"Due soon","Scheduled"))))) | T6: =IF($W6="","",IFERROR(IF(INDEX(FormData,$W6,f_Consent)&""="","",IF(ISNUMBER(SEARCH("yes",INDEX(FormData,$W6,f_Consent))),"Yes","No")),"")) | V6: =IF($U6="","",IF($W6="","not found","✓")) | W6: =IF($U6="","",IFERROR(MATCH($U6,INDEX(FormData,0,f_Id),0),IFERROR(MATCH(--$U6,INDEX(FormData,0,f_Id),0),IFERROR(MATCH($U6&"",INDEX(FormData,0,f_Id),0),"")))) | X6: =IF(AND($B6<>"",$B6='Event Report'!$C$3),ROW(),"") | Y6: =IF(AND($P6="✓",$R6=""),IF($Q6="",90000,$Q6)+ROW()/100000,"") | Z6: =IF(OR($U6<>"",$D6<>"",$E6<>"",$N6<>""),1,"")
A7: P-0003 | B7: =IF(AND($U7="",$C7=""),"",IFERROR(INDEX(EvID,MATCH(INDEX(FormData,$W7,f_Event),EvID,0)),IFERROR(INDEX(EvID,MATCH(INDEX(FormData,$W7,f_Event),EvName,0)),IFERROR(INDEX(EvID,MATCH(INT($C7),EvDate,0)),"")))) | C7: =IF($W7="","",INDEX(FormData,$W7,f_Time)) | D7: =IF($W7="","",IFERROR(UPPER(LEFT(TRIM(INDEX(FormData,$W7,f_Name)),1)&IFERROR(MID(TRIM(INDEX(FormData,$W7,f_Name)),FIND("^",SUBSTITUTE(TRIM(INDEX(FormData,$W7,f_Name))," ","^",LEN(TRIM(INDEX(FormData,$W7,f_Name)))-LEN(SUBSTITUTE(TRIM(INDEX(FormData,$W7,f_Name))," ",""))))+1,1),"")),"")) | E7: =IF($W7="","",IFERROR(IF(SUMPRODUCT(MAX((WhoKW<>"")*ISNUMBER(SEARCH(WhoKW,INDEX(FormData,$W7,f_Who)&""))*(ROW(WhoKW)-MIN(ROW(WhoKW))+1)))=0,"",INDEX(WhoVal,SUMPRODUCT(MAX((WhoKW<>"")*ISNUMBER(SEARCH(WhoKW,INDEX(FormData,$W7,f_Who)&""))*(ROW(WhoKW)-MIN(ROW(WhoKW))+1))))),"")) | F7: =IF($W7="","",TRIM(IFERROR(INDEX(FormData,$W7,f_Org1)&"","")&" "&IFERROR(INDEX(FormData,$W7,f_Org2)&"",""))) | G7: =IF($W7="","",IFERROR(INDEX(FormData,$W7,f_Region)&"","")) | H7: =IF($W7="","",IFERROR(IF(SUMPRODUCT(MAX((SitKW<>"")*ISNUMBER(SEARCH(SitKW,INDEX(FormData,$W7,f_Sit)&""))*(ROW(SitKW)-MIN(ROW(SitKW))+1)))=0,"",INDEX(SitVal,SUMPRODUCT(MAX((SitKW<>"")*ISNUMBER(SEARCH(SitKW,INDEX(FormData,$W7,f_Sit)&""))*(ROW(SitKW)-MIN(ROW(SitKW))+1))))),"")) | I7: =IF($W7="","",IFERROR(INDEX(FormData,$W7,f_Appr)&"","")) | J7: =IF($W7="","",IFERROR(INDEX(FormData,$W7,f_Trade)&"","")) | S7: =IF($P7<>"✓","",IF($R7<>"","Done",IF($Q7="","Open — no date",IF($Q7<TODAY(),"Overdue",IF($Q7-TODAY()<=DueSoon,"Due soon","Scheduled"))))) | T7: =IF($W7="","",IFERROR(IF(INDEX(FormData,$W7,f_Consent)&""="","",IF(ISNUMBER(SEARCH("yes",INDEX(FormData,$W7,f_Consent))),"Yes","No")),"")) | V7: =IF($U7="","",IF($W7="","not found","✓")) | W7: =IF($U7="","",IFERROR(MATCH($U7,INDEX(FormData,0,f_Id),0),IFERROR(MATCH(--$U7,INDEX(FormData,0,f_Id),0),IFERROR(MATCH($U7&"",INDEX(FormData,0,f_Id),0),"")))) | X7: =IF(AND($B7<>"",$B7='Event Report'!$C$3),ROW(),"") | Y7: =IF(AND($P7="✓",$R7=""),IF($Q7="",90000,$Q7)+ROW()/100000,"") | Z7: =IF(OR($U7<>"",$D7<>"",$E7<>"",$N7<>""),1,"")
A8: P-0004 | B8: =IF(AND($U8="",$C8=""),"",IFERROR(INDEX(EvID,MATCH(INDEX(FormData,$W8,f_Event),EvID,0)),IFERROR(INDEX(EvID,MATCH(INDEX(FormData,$W8,f_Event),EvName,0)),IFERROR(INDEX(EvID,MATCH(INT($C8),EvDate,0)),"")))) | C8: =IF($W8="","",INDEX(FormData,$W8,f_Time)) | D8: =IF($W8="","",IFERROR(UPPER(LEFT(TRIM(INDEX(FormData,$W8,f_Name)),1)&IFERROR(MID(TRIM(INDEX(FormData,$W8,f_Name)),FIND("^",SUBSTITUTE(TRIM(INDEX(FormData,$W8,f_Name))," ","^",LEN(TRIM(INDEX(FormData,$W8,f_Name)))-LEN(SUBSTITUTE(TRIM(INDEX(FormData,$W8,f_Name))," ",""))))+1,1),"")),"")) | E8: =IF($W8="","",IFERROR(IF(SUMPRODUCT(MAX((WhoKW<>"")*ISNUMBER(SEARCH(WhoKW,INDEX(FormData,$W8,f_Who)&""))*(ROW(WhoKW)-MIN(ROW(WhoKW))+1)))=0,"",INDEX(WhoVal,SUMPRODUCT(MAX((WhoKW<>"")*ISNUMBER(SEARCH(WhoKW,INDEX(FormData,$W8,f_Who)&""))*(ROW(WhoKW)-MIN(ROW(WhoKW))+1))))),"")) | F8: =IF($W8="","",TRIM(IFERROR(INDEX(FormData,$W8,f_Org1)&"","")&" "&IFERROR(INDEX(FormData,$W8,f_Org2)&"",""))) | G8: =IF($W8="","",IFERROR(INDEX(FormData,$W8,f_Region)&"","")) | H8: =IF($W8="","",IFERROR(IF(SUMPRODUCT(MAX((SitKW<>"")*ISNUMBER(SEARCH(SitKW,INDEX(FormData,$W8,f_Sit)&""))*(ROW(SitKW)-MIN(ROW(SitKW))+1)))=0,"",INDEX(SitVal,SUMPRODUCT(MAX((SitKW<>"")*ISNUMBER(SEARCH(SitKW,INDEX(FormData,$W8,f_Sit)&""))*(ROW(SitKW)-MIN(ROW(SitKW))+1))))),"")) | I8: =IF($W8="","",IFERROR(INDEX(FormData,$W8,f_Appr)&"","")) | J8: =IF($W8="","",IFERROR(INDEX(FormData,$W8,f_Trade)&"","")) | S8: =IF($P8<>"✓","",IF($R8<>"","Done",IF($Q8="","Open — no date",IF($Q8<TODAY(),"Overdue",IF($Q8-TODAY()<=DueSoon,"Due soon","Scheduled"))))) | T8: =IF($W8="","",IFERROR(IF(INDEX(FormData,$W8,f_Consent)&""="","",IF(ISNUMBER(SEARCH("yes",INDEX(FormData,$W8,f_Consent))),"Yes","No")),"")) | V8: =IF($U8="","",IF($W8="","not found","✓")) | W8: =IF($U8="","",IFERROR(MATCH($U8,INDEX(FormData,0,f_Id),0),IFERROR(MATCH(--$U8,INDEX(FormData,0,f_Id),0),IFERROR(MATCH($U8&"",INDEX(FormData,0,f_Id),0),"")))) | X8: =IF(AND($B8<>"",$B8='Event Report'!$C$3),ROW(),"") | Y8: =IF(AND($P8="✓",$R8=""),IF($Q8="",90000,$Q8)+ROW()/100000,"") | Z8: =IF(OR($U8<>"",$D8<>"",$E8<>"",$N8<>""),1,"")
A9: P-0005 | B9: =IF(AND($U9="",$C9=""),"",IFERROR(INDEX(EvID,MATCH(INDEX(FormData,$W9,f_Event),EvID,0)),IFERROR(INDEX(EvID,MATCH(INDEX(FormData,$W9,f_Event),EvName,0)),IFERROR(INDEX(EvID,MATCH(INT($C9),EvDate,0)),"")))) | C9: =IF($W9="","",INDEX(FormData,$W9,f_Time)) | D9: =IF($W9="","",IFERROR(UPPER(LEFT(TRIM(INDEX(FormData,$W9,f_Name)),1)&IFERROR(MID(TRIM(INDEX(FormData,$W9,f_Name)),FIND("^",SUBSTITUTE(TRIM(INDEX(FormData,$W9,f_Name))," ","^",LEN(TRIM(INDEX(FormData,$W9,f_Name)))-LEN(SUBSTITUTE(TRIM(INDEX(FormData,$W9,f_Name))," ",""))))+1,1),"")),"")) | E9: =IF($W9="","",IFERROR(IF(SUMPRODUCT(MAX((WhoKW<>"")*ISNUMBER(SEARCH(WhoKW,INDEX(FormData,$W9,f_Who)&""))*(ROW(WhoKW)-MIN(ROW(WhoKW))+1)))=0,"",INDEX(WhoVal,SUMPRODUCT(MAX((WhoKW<>"")*ISNUMBER(SEARCH(WhoKW,INDEX(FormData,$W9,f_Who)&""))*(ROW(WhoKW)-MIN(ROW(WhoKW))+1))))),"")) | F9: =IF($W9="","",TRIM(IFERROR(INDEX(FormData,$W9,f_Org1)&"","")&" "&IFERROR(INDEX(FormData,$W9,f_Org2)&"",""))) | G9: =IF($W9="","",IFERROR(INDEX(FormData,$W9,f_Region)&"","")) | H9: =IF($W9="","",IFERROR(IF(SUMPRODUCT(MAX((SitKW<>"")*ISNUMBER(SEARCH(SitKW,INDEX(FormData,$W9,f_Sit)&""))*(ROW(SitKW)-MIN(ROW(SitKW))+1)))=0,"",INDEX(SitVal,SUMPRODUCT(MAX((SitKW<>"")*ISNUMBER(SEARCH(SitKW,INDEX(FormData,$W9,f_Sit)&""))*(ROW(SitKW)-MIN(ROW(SitKW))+1))))),"")) | I9: =IF($W9="","",IFERROR(INDEX(FormData,$W9,f_Appr)&"","")) | J9: =IF($W9="","",IFERROR(INDEX(FormData,$W9,f_Trade)&"","")) | S9: =IF($P9<>"✓","",IF($R9<>"","Done",IF($Q9="","Open — no date",IF($Q9<TODAY(),"Overdue",IF($Q9-TODAY()<=DueSoon,"Due soon","Scheduled"))))) | T9: =IF($W9="","",IFERROR(IF(INDEX(FormData,$W9,f_Consent)&""="","",IF(ISNUMBER(SEARCH("yes",INDEX(FormData,$W9,f_Consent))),"Yes","No")),"")) | V9: =IF($U9="","",IF($W9="","not found","✓")) | W9: =IF($U9="","",IFERROR(MATCH($U9,INDEX(FormData,0,f_Id),0),IFERROR(MATCH(--$U9,INDEX(FormData,0,f_Id),0),IFERROR(MATCH($U9&"",INDEX(FormData,0,f_Id),0),"")))) | X9: =IF(AND($B9<>"",$B9='Event Report'!$C$3),ROW(),"") | Y9: =IF(AND($P9="✓",$R9=""),IF($Q9="",90000,$Q9)+ROW()/100000,"") | Z9: =IF(OR($U9<>"",$D9<>"",$E9<>"",$N9<>""),1,"")
A10: P-0006 | B10: =IF(AND($U10="",$C10=""),"",IFERROR(INDEX(EvID,MATCH(INDEX(FormData,$W10,f_Event),EvID,0)),IFERROR(INDEX(EvID,MATCH(INDEX(FormData,$W10,f_Event),EvName,0)),IFERROR(INDEX(EvID,MATCH(INT($C10),EvDate,0)),"")))) | C10: =IF($W10="","",INDEX(FormData,$W10,f_Time)) | D10: =IF($W10="","",IFERROR(UPPER(LEFT(TRIM(INDEX(FormData,$W10,f_Name)),1)&IFERROR(MID(TRIM(INDEX(FormData,$W10,f_Name)),FIND("^",SUBSTITUTE(TRIM(INDEX(FormData,$W10,f_Name))," ","^",LEN(TRIM(INDEX(FormData,$W10,f_Name)))-LEN(SUBSTITUTE(TRIM(INDEX(FormData,$W10,f_Name))," ",""))))+1,1),"")),"")) | E10: =IF($W10="","",IFERROR(IF(SUMPRODUCT(MAX((WhoKW<>"")*ISNUMBER(SEARCH(WhoKW,INDEX(FormData,$W10,f_Who)&""))*(ROW(WhoKW)-MIN(ROW(WhoKW))+1)))=0,"",INDEX(WhoVal,SUMPRODUCT(MAX((WhoKW<>"")*ISNUMBER(SEARCH(WhoKW,INDEX(FormData,$W10,f_Who)&""))*(ROW(WhoKW)-MIN(ROW(WhoKW))+1))))),"")) | F10: =IF($W10="","",TRIM(IFERROR(INDEX(FormData,$W10,f_Org1)&"","")&" "&IFERROR(INDEX(FormData,$W10,f_Org2)&"",""))) | G10: =IF($W10="","",IFERROR(INDEX(FormData,$W10,f_Region)&"","")) | H10: =IF($W10="","",IFERROR(IF(SUMPRODUCT(MAX((SitKW<>"")*ISNUMBER(SEARCH(SitKW,INDEX(FormData,$W10,f_Sit)&""))*(ROW(SitKW)-MIN(ROW(SitKW))+1)))=0,"",INDEX(SitVal,SUMPRODUCT(MAX((SitKW<>"")*ISNUMBER(SEARCH(SitKW,INDEX(FormData,$W10,f_Sit)&""))*(ROW(SitKW)-MIN(ROW(SitKW))+1))))),"")) | I10: =IF($W10="","",IFERROR(INDEX(FormData,$W10,f_Appr)&"","")) | J10: =IF($W10="","",IFERROR(INDEX(FormData,$W10,f_Trade)&"","")) | S10: =IF($P10<>"✓","",IF($R10<>"","Done",IF($Q10="","Open — no date",IF($Q10<TODAY(),"Overdue",IF($Q10-TODAY()<=DueSoon,"Due soon","Scheduled"))))) | T10: =IF($W10="","",IFERROR(IF(INDEX(FormData,$W10,f_Consent)&""="","",IF(ISNUMBER(SEARCH("yes",INDEX(FormData,$W10,f_Consent))),"Yes","No")),"")) | V10: =IF($U10="","",IF($W10="","not found","✓")) | W10: =IF($U10="","",IFERROR(MATCH($U10,INDEX(FormData,0,f_Id),0),IFERROR(MATCH(--$U10,INDEX(FormData,0,f_Id),0),IFERROR(MATCH($U10&"",INDEX(FormData,0,f_Id),0),"")))) | X10: =IF(AND($B10<>"",$B10='Event Report'!$C$3),ROW(),"") | Y10: =IF(AND($P10="✓",$R10=""),IF($Q10="",90000,$Q10)+ROW()/100000,"") | Z10: =IF(OR($U10<>"",$D10<>"",$E10<>"",$N10<>""),1,"")
A11: P-0007 | B11: =IF(AND($U11="",$C11=""),"",IFERROR(INDEX(EvID,MATCH(INDEX(FormData,$W11,f_Event),EvID,0)),IFERROR(INDEX(EvID,MATCH(INDEX(FormData,$W11,f_Event),EvName,0)),IFERROR(INDEX(EvID,MATCH(INT($C11),EvDate,0)),"")))) | C11: =IF($W11="","",INDEX(FormData,$W11,f_Time)) | D11: =IF($W11="","",IFERROR(UPPER(LEFT(TRIM(INDEX(FormData,$W11,f_Name)),1)&IFERROR(MID(TRIM(INDEX(FormData,$W11,f_Name)),FIND("^",SUBSTITUTE(TRIM(INDEX(FormData,$W11,f_Name))," ","^",LEN(TRIM(INDEX(FormData,$W11,f_Name)))-LEN(SUBSTITUTE(TRIM(INDEX(FormData,$W11,f_Name))," ",""))))+1,1),"")),"")) | E11: =IF($W11="","",IFERROR(IF(SUMPRODUCT(MAX((WhoKW<>"")*ISNUMBER(SEARCH(WhoKW,INDEX(FormData,$W11,f_Who)&""))*(ROW(WhoKW)-MIN(ROW(WhoKW))+1)))=0,"",INDEX(WhoVal,SUMPRODUCT(MAX((WhoKW<>"")*ISNUMBER(SEARCH(WhoKW,INDEX(FormData,$W11,f_Who)&""))*(ROW(WhoKW)-MIN(ROW(WhoKW))+1))))),"")) | F11: =IF($W11="","",TRIM(IFERROR(INDEX(FormData,$W11,f_Org1)&"","")&" "&IFERROR(INDEX(FormData,$W11,f_Org2)&"",""))) | G11: =IF($W11="","",IFERROR(INDEX(FormData,$W11,f_Region)&"","")) | H11: =IF($W11="","",IFERROR(IF(SUMPRODUCT(MAX((SitKW<>"")*ISNUMBER(SEARCH(SitKW,INDEX(FormData,$W11,f_Sit)&""))*(ROW(SitKW)-MIN(ROW(SitKW))+1)))=0,"",INDEX(SitVal,SUMPRODUCT(MAX((SitKW<>"")*ISNUMBER(SEARCH(SitKW,INDEX(FormData,$W11,f_Sit)&""))*(ROW(SitKW)-MIN(ROW(SitKW))+1))))),"")) | I11: =IF($W11="","",IFERROR(INDEX(FormData,$W11,f_Appr)&"","")) | J11: =IF($W11="","",IFERROR(INDEX(FormData,$W11,f_Trade)&"","")) | S11: =IF($P11<>"✓","",IF($R11<>"","Done",IF($Q11="","Open — no date",IF($Q11<TODAY(),"Overdue",IF($Q11-TODAY()<=DueSoon,"Due soon","Scheduled"))))) | T11: =IF($W11="","",IFERROR(IF(INDEX(FormData,$W11,f_Consent)&""="","",IF(ISNUMBER(SEARCH("yes",INDEX(FormData,$W11,f_Consent))),"Yes","No")),"")) | V11: =IF($U11="","",IF($W11="","not found","✓")) | W11: =IF($U11="","",IFERROR(MATCH($U11,INDEX(FormData,0,f_Id),0),IFERROR(MATCH(--$U11,INDEX(FormData,0,f_Id),0),IFERROR(MATCH($U11&"",INDEX(FormData,0,f_Id),0),"")))) | X11: =IF(AND($B11<>"",$B11='Event Report'!$C$3),ROW(),"") | Y11: =IF(AND($P11="✓",$R11=""),IF($Q11="",90000,$Q11)+ROW()/100000,"") | Z11: =IF(OR($U11<>"",$D11<>"",$E11<>"",$N11<>""),1,"")
A12: P-0008 | B12: =IF(AND($U12="",$C12=""),"",IFERROR(INDEX(EvID,MATCH(INDEX(FormData,$W12,f_Event),EvID,0)),IFERROR(INDEX(EvID,MATCH(INDEX(FormData,$W12,f_Event),EvName,0)),IFERROR(INDEX(EvID,MATCH(INT($C12),EvDate,0)),"")))) | C12: =IF($W12="","",INDEX(FormData,$W12,f_Time)) | D12: =IF($W12="","",IFERROR(UPPER(LEFT(TRIM(INDEX(FormData,$W12,f_Name)),1)&IFERROR(MID(TRIM(INDEX(FormData,$W12,f_Name)),FIND("^",SUBSTITUTE(TRIM(INDEX(FormData,$W12,f_Name))," ","^",LEN(TRIM(INDEX(FormData,$W12,f_Name)))-LEN(SUBSTITUTE(TRIM(INDEX(FormData,$W12,f_Name))," ",""))))+1,1),"")),"")) | E12: =IF($W12="","",IFERROR(IF(SUMPRODUCT(MAX((WhoKW<>"")*ISNUMBER(SEARCH(WhoKW,INDEX(FormData,$W12,f_Who)&""))*(ROW(WhoKW)-MIN(ROW(WhoKW))+1)))=0,"",INDEX(WhoVal,SUMPRODUCT(MAX((WhoKW<>"")*ISNUMBER(SEARCH(WhoKW,INDEX(FormData,$W12,f_Who)&""))*(ROW(WhoKW)-MIN(ROW(WhoKW))+1))))),"")) | F12: =IF($W12="","",TRIM(IFERROR(INDEX(FormData,$W12,f_Org1)&"","")&" "&IFERROR(INDEX(FormData,$W12,f_Org2)&"",""))) | G12: =IF($W12="","",IFERROR(INDEX(FormData,$W12,f_Region)&"","")) | H12: =IF($W12="","",IFERROR(IF(SUMPRODUCT(MAX((SitKW<>"")*ISNUMBER(SEARCH(SitKW,INDEX(FormData,$W12,f_Sit)&""))*(ROW(SitKW)-MIN(ROW(SitKW))+1)))=0,"",INDEX(SitVal,SUMPRODUCT(MAX((SitKW<>"")*ISNUMBER(SEARCH(SitKW,INDEX(FormData,$W12,f_Sit)&""))*(ROW(SitKW)-MIN(ROW(SitKW))+1))))),"")) | I12: =IF($W12="","",IFERROR(INDEX(FormData,$W12,f_Appr)&"","")) | J12: =IF($W12="","",IFERROR(INDEX(FormData,$W12,f_Trade)&"","")) | S12: =IF($P12<>"✓","",IF($R12<>"","Done",IF($Q12="","Open — no date",IF($Q12<TODAY(),"Overdue",IF($Q12-TODAY()<=DueSoon,"Due soon","Scheduled"))))) | T12: =IF($W12="","",IFERROR(IF(INDEX(FormData,$W12,f_Consent)&""="","",IF(ISNUMBER(SEARCH("yes",INDEX(FormData,$W12,f_Consent))),"Yes","No")),"")) | V12: =IF($U12="","",IF($W12="","not found","✓")) | W12: =IF($U12="","",IFERROR(MATCH($U12,INDEX(FormData,0,f_Id),0),IFERROR(MATCH(--$U12,INDEX(FormData,0,f_Id),0),IFERROR(MATCH($U12&"",INDEX(FormData,0,f_Id),0),"")))) | X12: =IF(AND($B12<>"",$B12='Event Report'!$C$3),ROW(),"") | Y12: =IF(AND($P12="✓",$R12=""),IF($Q12="",90000,$Q12)+ROW()/100000,"") | Z12: =IF(OR($U12<>"",$D12<>"",$E12<>"",$N12<>""),1,"")
A13: P-0009 | B13: =IF(AND($U13="",$C13=""),"",IFERROR(INDEX(EvID,MATCH(INDEX(FormData,$W13,f_Event),EvID,0)),IFERROR(INDEX(EvID,MATCH(INDEX(FormData,$W13,f_Event),EvName,0)),IFERROR(INDEX(EvID,MATCH(INT($C13),EvDate,0)),"")))) | C13: =IF($W13="","",INDEX(FormData,$W13,f_Time)) | D13: =IF($W13="","",IFERROR(UPPER(LEFT(TRIM(INDEX(FormData,$W13,f_Name)),1)&IFERROR(MID(TRIM(INDEX(FormData,$W13,f_Name)),FIND("^",SUBSTITUTE(TRIM(INDEX(FormData,$W13,f_Name))," ","^",LEN(TRIM(INDEX(FormData,$W13,f_Name)))-LEN(SUBSTITUTE(TRIM(INDEX(FormData,$W13,f_Name))," ",""))))+1,1),"")),"")) | E13: =IF($W13="","",IFERROR(IF(SUMPRODUCT(MAX((WhoKW<>"")*ISNUMBER(SEARCH(WhoKW,INDEX(FormData,$W13,f_Who)&""))*(ROW(WhoKW)-MIN(ROW(WhoKW))+1)))=0,"",INDEX(WhoVal,SUMPRODUCT(MAX((WhoKW<>"")*ISNUMBER(SEARCH(WhoKW,INDEX(FormData,$W13,f_Who)&""))*(ROW(WhoKW)-MIN(ROW(WhoKW))+1))))),"")) | F13: =IF($W13="","",TRIM(IFERROR(INDEX(FormData,$W13,f_Org1)&"","")&" "&IFERROR(INDEX(FormData,$W13,f_Org2)&"",""))) | G13: =IF($W13="","",IFERROR(INDEX(FormData,$W13,f_Region)&"","")) | H13: =IF($W13="","",IFERROR(IF(SUMPRODUCT(MAX((SitKW<>"")*ISNUMBER(SEARCH(SitKW,INDEX(FormData,$W13,f_Sit)&""))*(ROW(SitKW)-MIN(ROW(SitKW))+1)))=0,"",INDEX(SitVal,SUMPRODUCT(MAX((SitKW<>"")*ISNUMBER(SEARCH(SitKW,INDEX(FormData,$W13,f_Sit)&""))*(ROW(SitKW)-MIN(ROW(SitKW))+1))))),"")) | I13: =IF($W13="","",IFERROR(INDEX(FormData,$W13,f_Appr)&"","")) | J13: =IF($W13="","",IFERROR(INDEX(FormData,$W13,f_Trade)&"","")) | S13: =IF($P13<>"✓","",IF($R13<>"","Done",IF($Q13="","Open — no date",IF($Q13<TODAY(),"Overdue",IF($Q13-TODAY()<=DueSoon,"Due soon","Scheduled"))))) | T13: =IF($W13="","",IFERROR(IF(INDEX(FormData,$W13,f_Consent)&""="","",IF(ISNUMBER(SEARCH("yes",INDEX(FormData,$W13,f_Consent))),"Yes","No")),"")) | V13: =IF($U13="","",IF($W13="","not found","✓")) | W13: =IF($U13="","",IFERROR(MATCH($U13,INDEX(FormData,0,f_Id),0),IFERROR(MATCH(--$U13,INDEX(FormData,0,f_Id),0),IFERROR(MATCH($U13&"",INDEX(FormData,0,f_Id),0),"")))) | X13: =IF(AND($B13<>"",$B13='Event Report'!$C$3),ROW(),"") | Y13: =IF(AND($P13="✓",$R13=""),IF($Q13="",90000,$Q13)+ROW()/100000,"") | Z13: =IF(OR($U13<>"",$D13<>"",$E13<>"",$N13<>""),1,"")
A14: P-0010 | B14: =IF(AND($U14="",$C14=""),"",IFERROR(INDEX(EvID,MATCH(INDEX(FormData,$W14,f_Event),EvID,0)),IFERROR(INDEX(EvID,MATCH(INDEX(FormData,$W14,f_Event),EvName,0)),IFERROR(INDEX(EvID,MATCH(INT($C14),EvDate,0)),"")))) | C14: =IF($W14="","",INDEX(FormData,$W14,f_Time)) | D14: =IF($W14="","",IFERROR(UPPER(LEFT(TRIM(INDEX(FormData,$W14,f_Name)),1)&IFERROR(MID(TRIM(INDEX(FormData,$W14,f_Name)),FIND("^",SUBSTITUTE(TRIM(INDEX(FormData,$W14,f_Name))," ","^",LEN(TRIM(INDEX(FormData,$W14,f_Name)))-LEN(SUBSTITUTE(TRIM(INDEX(FormData,$W14,f_Name))," ",""))))+1,1),"")),"")) | E14: =IF($W14="","",IFERROR(IF(SUMPRODUCT(MAX((WhoKW<>"")*ISNUMBER(SEARCH(WhoKW,INDEX(FormData,$W14,f_Who)&""))*(ROW(WhoKW)-MIN(ROW(WhoKW))+1)))=0,"",INDEX(WhoVal,SUMPRODUCT(MAX((WhoKW<>"")*ISNUMBER(SEARCH(WhoKW,INDEX(FormData,$W14,f_Who)&""))*(ROW(WhoKW)-MIN(ROW(WhoKW))+1))))),"")) | F14: =IF($W14="","",TRIM(IFERROR(INDEX(FormData,$W14,f_Org1)&"","")&" "&IFERROR(INDEX(FormData,$W14,f_Org2)&"",""))) | G14: =IF($W14="","",IFERROR(INDEX(FormData,$W14,f_Region)&"","")) | H14: =IF($W14="","",IFERROR(IF(SUMPRODUCT(MAX((SitKW<>"")*ISNUMBER(SEARCH(SitKW,INDEX(FormData,$W14,f_Sit)&""))*(ROW(SitKW)-MIN(ROW(SitKW))+1)))=0,"",INDEX(SitVal,SUMPRODUCT(MAX((SitKW<>"")*ISNUMBER(SEARCH(SitKW,INDEX(FormData,$W14,f_Sit)&""))*(ROW(SitKW)-MIN(ROW(SitKW))+1))))),"")) | I14: =IF($W14="","",IFERROR(INDEX(FormData,$W14,f_Appr)&"","")) | J14: =IF($W14="","",IFERROR(INDEX(FormData,$W14,f_Trade)&"","")) | S14: =IF($P14<>"✓","",IF($R14<>"","Done",IF($Q14="","Open — no date",IF($Q14<TODAY(),"Overdue",IF($Q14-TODAY()<=DueSoon,"Due soon","Scheduled"))))) | T14: =IF($W14="","",IFERROR(IF(INDEX(FormData,$W14,f_Consent)&""="","",IF(ISNUMBER(SEARCH("yes",INDEX(FormData,$W14,f_Consent))),"Yes","No")),"")) | V14: =IF($U14="","",IF($W14="","not found","✓")) | W14: =IF($U14="","",IFERROR(MATCH($U14,INDEX(FormData,0,f_Id),0),IFERROR(MATCH(--$U14,INDEX(FormData,0,f_Id),0),IFERROR(MATCH($U14&"",INDEX(FormData,0,f_Id),0),"")))) | X14: =IF(AND($B14<>"",$B14='Event Report'!$C$3),ROW(),"") | Y14: =IF(AND($P14="✓",$R14=""),IF($Q14="",90000,$Q14)+ROW()/100000,"") | Z14: =IF(OR($U14<>"",$D14<>"",$E14<>"",$N14<>""),1,"")
A15: P-0011 | B15: =IF(AND($U15="",$C15=""),"",IFERROR(INDEX(EvID,MATCH(INDEX(FormData,$W15,f_Event),EvID,0)),IFERROR(INDEX(EvID,MATCH(INDEX(FormData,$W15,f_Event),EvName,0)),IFERROR(INDEX(EvID,MATCH(INT($C15),EvDate,0)),"")))) | C15: =IF($W15="","",INDEX(FormData,$W15,f_Time)) | D15: =IF($W15="","",IFERROR(UPPER(LEFT(TRIM(INDEX(FormData,$W15,f_Name)),1)&IFERROR(MID(TRIM(INDEX(FormData,$W15,f_Name)),FIND("^",SUBSTITUTE(TRIM(INDEX(FormData,$W15,f_Name))," ","^",LEN(TRIM(INDEX(FormData,$W15,f_Name)))-LEN(SUBSTITUTE(TRIM(INDEX(FormData,$W15,f_Name))," ",""))))+1,1),"")),"")) | E15: =IF($W15="","",IFERROR(IF(SUMPRODUCT(MAX((WhoKW<>"")*ISNUMBER(SEARCH(WhoKW,INDEX(FormData,$W15,f_Who)&""))*(ROW(WhoKW)-MIN(ROW(WhoKW))+1)))=0,"",INDEX(WhoVal,SUMPRODUCT(MAX((WhoKW<>"")*ISNUMBER(SEARCH(WhoKW,INDEX(FormData,$W15,f_Who)&""))*(ROW(WhoKW)-MIN(ROW(WhoKW))+1))))),"")) | F15: =IF($W15="","",TRIM(IFERROR(INDEX(FormData,$W15,f_Org1)&"","")&" "&IFERROR(INDEX(FormData,$W15,f_Org2)&"",""))) | G15: =IF($W15="","",IFERROR(INDEX(FormData,$W15,f_Region)&"","")) | H15: =IF($W15="","",IFERROR(IF(SUMPRODUCT(MAX((SitKW<>"")*ISNUMBER(SEARCH(SitKW,INDEX(FormData,$W15,f_Sit)&""))*(ROW(SitKW)-MIN(ROW(SitKW))+1)))=0,"",INDEX(SitVal,SUMPRODUCT(MAX((SitKW<>"")*ISNUMBER(SEARCH(SitKW,INDEX(FormData,$W15,f_Sit)&""))*(ROW(SitKW)-MIN(ROW(SitKW))+1))))),"")) | I15: =IF($W15="","",IFERROR(INDEX(FormData,$W15,f_Appr)&"","")) | J15: =IF($W15="","",IFERROR(INDEX(FormData,$W15,f_Trade)&"","")) | S15: =IF($P15<>"✓","",IF($R15<>"","Done",IF($Q15="","Open — no date",IF($Q15<TODAY(),"Overdue",IF($Q15-TODAY()<=DueSoon,"Due soon","Scheduled"))))) | T15: =IF($W15="","",IFERROR(IF(INDEX(FormData,$W15,f_Consent)&""="","",IF(ISNUMBER(SEARCH("yes",INDEX(FormData,$W15,f_Consent))),"Yes","No")),"")) | V15: =IF($U15="","",IF($W15="","not found","✓")) | W15: =IF($U15="","",IFERROR(MATCH($U15,INDEX(FormData,0,f_Id),0),IFERROR(MATCH(--$U15,INDEX(FormData,0,f_Id),0),IFERROR(MATCH($U15&"",INDEX(FormData,0,f_Id),0),"")))) | X15: =IF(AND($B15<>"",$B15='Event Report'!$C$3),ROW(),"") | Y15: =IF(AND($P15="✓",$R15=""),IF($Q15="",90000,$Q15)+ROW()/100000,"") | Z15: =IF(OR($U15<>"",$D15<>"",$E15<>"",$N15<>""),1,"")
A16: P-0012 | B16: =IF(AND($U16="",$C16=""),"",IFERROR(INDEX(EvID,MATCH(INDEX(FormData,$W16,f_Event),EvID,0)),IFERROR(INDEX(EvID,MATCH(INDEX(FormData,$W16,f_Event),EvName,0)),IFERROR(INDEX(EvID,MATCH(INT($C16),EvDate,0)),"")))) | C16: =IF($W16="","",INDEX(FormData,$W16,f_Time)) | D16: =IF($W16="","",IFERROR(UPPER(LEFT(TRIM(INDEX(FormData,$W16,f_Name)),1)&IFERROR(MID(TRIM(INDEX(FormData,$W16,f_Name)),FIND("^",SUBSTITUTE(TRIM(INDEX(FormData,$W16,f_Name))," ","^",LEN(TRIM(INDEX(FormData,$W16,f_Name)))-LEN(SUBSTITUTE(TRIM(INDEX(FormData,$W16,f_Name))," ",""))))+1,1),"")),"")) | E16: =IF($W16="","",IFERROR(IF(SUMPRODUCT(MAX((WhoKW<>"")*ISNUMBER(SEARCH(WhoKW,INDEX(FormData,$W16,f_Who)&""))*(ROW(WhoKW)-MIN(ROW(WhoKW))+1)))=0,"",INDEX(WhoVal,SUMPRODUCT(MAX((WhoKW<>"")*ISNUMBER(SEARCH(WhoKW,INDEX(FormData,$W16,f_Who)&""))*(ROW(WhoKW)-MIN(ROW(WhoKW))+1))))),"")) | F16: =IF($W16="","",TRIM(IFERROR(INDEX(FormData,$W16,f_Org1)&"","")&" "&IFERROR(INDEX(FormData,$W16,f_Org2)&"",""))) | G16: =IF($W16="","",IFERROR(INDEX(FormData,$W16,f_Region)&"","")) | H16: =IF($W16="","",IFERROR(IF(SUMPRODUCT(MAX((SitKW<>"")*ISNUMBER(SEARCH(SitKW,INDEX(FormData,$W16,f_Sit)&""))*(ROW(SitKW)-MIN(ROW(SitKW))+1)))=0,"",INDEX(SitVal,SUMPRODUCT(MAX((SitKW<>"")*ISNUMBER(SEARCH(SitKW,INDEX(FormData,$W16,f_Sit)&""))*(ROW(SitKW)-MIN(ROW(SitKW))+1))))),"")) | I16: =IF($W16="","",IFERROR(INDEX(FormData,$W16,f_Appr)&"","")) | J16: =IF($W16="","",IFERROR(INDEX(FormData,$W16,f_Trade)&"","")) | S16: =IF($P16<>"✓","",IF($R16<>"","Done",IF($Q16="","Open — no date",IF($Q16<TODAY(),"Overdue",IF($Q16-TODAY()<=DueSoon,"Due soon","Scheduled"))))) | T16: =IF($W16="","",IFERROR(IF(INDEX(FormData,$W16,f_Consent)&""="","",IF(ISNUMBER(SEARCH("yes",INDEX(FormData,$W16,f_Consent))),"Yes","No")),"")) | V16: =IF($U16="","",IF($W16="","not found","✓")) | W16: =IF($U16="","",IFERROR(MATCH($U16,INDEX(FormData,0,f_Id),0),IFERROR(MATCH(--$U16,INDEX(FormData,0,f_Id),0),IFERROR(MATCH($U16&"",INDEX(FormData,0,f_Id),0),"")))) | X16: =IF(AND($B16<>"",$B16='Event Report'!$C$3),ROW(),"") | Y16: =IF(AND($P16="✓",$R16=""),IF($Q16="",90000,$Q16)+ROW()/100000,"") | Z16: =IF(OR($U16<>"",$D16<>"",$E16<>"",$N16<>""),1,"")
... A604: P-0600 | B604: =IF(AND($U604="",$C604=""),"",IFERROR(INDEX(EvID,MATCH(INDEX(FormData,$W604,f_Event),EvID,0)),IFERROR(INDEX(EvID,MATCH(INDEX(FormData,$W604,f_Event),EvName,0)),IFERROR(INDEX(EvID,MATCH(INT($C604),EvDate,0)),"")))) | C604: =IF($W604="","",INDEX(FormData,$W604,f_Time)) | D604: =IF($W604="","",IFERROR(UPPER(LEFT(TRIM(INDEX(FormData,$W604,f_Name)),1)&IFERROR(MID(TRIM(INDEX(FormData,$W604,f_Name)),FIND("^",SUBSTITUTE(TRIM(INDEX(FormData,$W604,f_Name))," ","^",LEN(TRIM(INDEX(FormData,$W604,f_Name)))-LEN(SUBSTITUTE(TRIM(INDEX(FormData,$W604,f_Name))," ",""))))+1,1),"")),"")) | E604: =IF($W604="","",IFERROR(IF(SUMPRODUCT(MAX((WhoKW<>"")*ISNUMBER(SEARCH(WhoKW,INDEX(FormData,$W604,f_Who)&""))*(ROW(WhoKW)-MIN(ROW(WhoKW))+1)))=0,"",INDEX(WhoVal,SUMPRODUCT(MAX((WhoKW<>"")*ISNUMBER(SEARCH(WhoKW,INDEX(FormData,$W604,f_Who)&""))*(ROW(WhoKW)-MIN(ROW(WhoKW))+1))))),"")) | F604: =IF($W604="","",TRIM(IFERROR(INDEX(FormData,$W604,f_Org1)&"","")&" "&IFERROR(INDEX(FormData,$W604,f_Org2)&"",""))) | G604: =IF($W604="","",IFERROR(INDEX(FormData,$W604,f_Region)&"","")) | H604: =IF($W604="","",IFERROR(IF(SUMPRODUCT(MAX((SitKW<>"")*ISNUMBER(SEARCH(SitKW,INDEX(FormData,$W604,f_Sit)&""))*(ROW(SitKW)-MIN(ROW(SitKW))+1)))=0,"",INDEX(SitVal,SUMPRODUCT(MAX((SitKW<>"")*ISNUMBER(SEARCH(SitKW,INDEX(FormData,$W604,f_Sit)&""))*(ROW(SitKW)-MIN(ROW(SitKW))+1))))),"")) | I604: =IF($W604="","",IFERROR(INDEX(FormData,$W604,f_Appr)&"","")) | J604: =IF($W604="","",IFERROR(INDEX(FormData,$W604,f_Trade)&"","")) | S604: =IF($P604<>"✓","",IF($R604<>"","Done",IF($Q604="","Open — no date",IF($Q604<TODAY(),"Overdue",IF($Q604-TODAY()<=DueSoon,"Due soon","Scheduled"))))) | T604: =IF($W604="","",IFERROR(IF(INDEX(FormData,$W604,f_Consent)&""="","",IF(ISNUMBER(SEARCH("yes",INDEX(FormData,$W604,f_Consent))),"Yes","No")),"")) | V604: =IF($U604="","",IF($W604="","not found","✓")) | W604: =IF($U604="","",IFERROR(MATCH($U604,INDEX(FormData,0,f_Id),0),IFERROR(MATCH(--$U604,INDEX(FormData,0,f_Id),0),IFERROR(MATCH($U604&"",INDEX(FormData,0,f_Id),0),"")))) | X604: =IF(AND($B604<>"",$B604='Event Report'!$C$3),ROW(),"") | Y604: =IF(AND($P604="✓",$R604=""),IF($Q604="",90000,$Q604)+ROW()/100000,"") | Z604: =IF(OR($U604<>"",$D604<>"",$E604<>"",$N604<>""),1,"")

Sheet New Sign-Ups
A1: New Sign-Ups
A2: Everyone who has filled in the form, newest at the bottom. Anyone marked → add isn't on People yet.
A3: Not yet on People: | C3: =COUNTIF(G5:G1004,"→ add") | D3: → Filter column G to “→ add”, then type each Response ID into a blank row on People (column U).
A4: # | B4: Response ID | C4: Submitted | D4: Initials | E4: Event (by date) | F4: Contact Type (from form) | G4: On People? | H4: _row | I4: Wants help with (from form)
A5: 1 | B5: =IF($H5="","",INDEX(FormData,$H5,f_Id)) | C5: =IF($H5="","",IFERROR(INDEX(FormData,$H5,f_Time),"")) | D5: =IF($H5="","",IFERROR(UPPER(LEFT(TRIM(INDEX(FormData,$H5,f_Name)),1)&IFERROR(MID(TRIM(INDEX(FormData,$H5,f_Name)),FIND("^",SUBSTITUTE(TRIM(INDEX(FormData,$H5,f_Name))," ","^",LEN(TRIM(INDEX(FormData,$H5,f_Name)))-LEN(SUBSTITUTE(TRIM(INDEX(FormData,$H5,f_Name))," ",""))))+1,1),"")),"")) | E5: =IF($H5="","",IFERROR(INDEX(EvID,MATCH(INDEX(FormData,$H5,f_Event),EvID,0)),IFERROR(INDEX(EvID,MATCH(INDEX(FormData,$H5,f_Event),EvName,0)),IFERROR(INDEX(EvID,MATCH(INT($C5),EvDate,0)),"(no event that day)")))) | F5: =IF($H5="","",IFERROR(IF(SUMPRODUCT(MAX((WhoKW<>"")*ISNUMBER(SEARCH(WhoKW,INDEX(FormData,$H5,f_Who)&""))*(ROW(WhoKW)-MIN(ROW(WhoKW))+1)))=0,"",INDEX(WhoVal,SUMPRODUCT(MAX((WhoKW<>"")*ISNUMBER(SEARCH(WhoKW,INDEX(FormData,$H5,f_Who)&""))*(ROW(WhoKW)-MIN(ROW(WhoKW))+1))))),"")) | G5: =IF($H5="","",IF(COUNTIF(People!$U$5:$U$604,$B5)+COUNTIF(People!$U$5:$U$604,$B5&"")>0,"✓ logged","→ add")) | H5: =IFERROR(IF(INDEX(FormData,2,f_Id)&""="","",2),"") | I5: =IF($H5="","",IFERROR(INDEX(FormData,$H5,f_Need)&"",""))
A6: 2 | B6: =IF($H6="","",INDEX(FormData,$H6,f_Id)) | C6: =IF($H6="","",IFERROR(INDEX(FormData,$H6,f_Time),"")) | D6: =IF($H6="","",IFERROR(UPPER(LEFT(TRIM(INDEX(FormData,$H6,f_Name)),1)&IFERROR(MID(TRIM(INDEX(FormData,$H6,f_Name)),FIND("^",SUBSTITUTE(TRIM(INDEX(FormData,$H6,f_Name))," ","^",LEN(TRIM(INDEX(FormData,$H6,f_Name)))-LEN(SUBSTITUTE(TRIM(INDEX(FormData,$H6,f_Name))," ",""))))+1,1),"")),"")) | E6: =IF($H6="","",IFERROR(INDEX(EvID,MATCH(INDEX(FormData,$H6,f_Event),EvID,0)),IFERROR(INDEX(EvID,MATCH(INDEX(FormData,$H6,f_Event),EvName,0)),IFERROR(INDEX(EvID,MATCH(INT($C6),EvDate,0)),"(no event that day)")))) | F6: =IF($H6="","",IFERROR(IF(SUMPRODUCT(MAX((WhoKW<>"")*ISNUMBER(SEARCH(WhoKW,INDEX(FormData,$H6,f_Who)&""))*(ROW(WhoKW)-MIN(ROW(WhoKW))+1)))=0,"",INDEX(WhoVal,SUMPRODUCT(MAX((WhoKW<>"")*ISNUMBER(SEARCH(WhoKW,INDEX(FormData,$H6,f_Who)&""))*(ROW(WhoKW)-MIN(ROW(WhoKW))+1))))),"")) | G6: =IF($H6="","",IF(COUNTIF(People!$U$5:$U$604,$B6)+COUNTIF(People!$U$5:$U$604,$B6&"")>0,"✓ logged","→ add")) | H6: =IFERROR(IF(INDEX(FormData,3,f_Id)&""="","",3),"") | I6: =IF($H6="","",IFERROR(INDEX(FormData,$H6,f_Need)&"",""))
A7: 3 | B7: =IF($H7="","",INDEX(FormData,$H7,f_Id)) | C7: =IF($H7="","",IFERROR(INDEX(FormData,$H7,f_Time),"")) | D7: =IF($H7="","",IFERROR(UPPER(LEFT(TRIM(INDEX(FormData,$H7,f_Name)),1)&IFERROR(MID(TRIM(INDEX(FormData,$H7,f_Name)),FIND("^",SUBSTITUTE(TRIM(INDEX(FormData,$H7,f_Name))," ","^",LEN(TRIM(INDEX(FormData,$H7,f_Name)))-LEN(SUBSTITUTE(TRIM(INDEX(FormData,$H7,f_Name))," ",""))))+1,1),"")),"")) | E7: =IF($H7="","",IFERROR(INDEX(EvID,MATCH(INDEX(FormData,$H7,f_Event),EvID,0)),IFERROR(INDEX(EvID,MATCH(INDEX(FormData,$H7,f_Event),EvName,0)),IFERROR(INDEX(EvID,MATCH(INT($C7),EvDate,0)),"(no event that day)")))) | F7: =IF($H7="","",IFERROR(IF(SUMPRODUCT(MAX((WhoKW<>"")*ISNUMBER(SEARCH(WhoKW,INDEX(FormData,$H7,f_Who)&""))*(ROW(WhoKW)-MIN(ROW(WhoKW))+1)))=0,"",INDEX(WhoVal,SUMPRODUCT(MAX((WhoKW<>"")*ISNUMBER(SEARCH(WhoKW,INDEX(FormData,$H7,f_Who)&""))*(ROW(WhoKW)-MIN(ROW(WhoKW))+1))))),"")) | G7: =IF($H7="","",IF(COUNTIF(People!$U$5:$U$604,$B7)+COUNTIF(People!$U$5:$U$604,$B7&"")>0,"✓ logged","→ add")) | H7: =IFERROR(IF(INDEX(FormData,4,f_Id)&""="","",4),"") | I7: =IF($H7="","",IFERROR(INDEX(FormData,$H7,f_Need)&"",""))
A8: 4 | B8: =IF($H8="","",INDEX(FormData,$H8,f_Id)) | C8: =IF($H8="","",IFERROR(INDEX(FormData,$H8,f_Time),"")) | D8: =IF($H8="","",IFERROR(UPPER(LEFT(TRIM(INDEX(FormData,$H8,f_Name)),1)&IFERROR(MID(TRIM(INDEX(FormData,$H8,f_Name)),FIND("^",SUBSTITUTE(TRIM(INDEX(FormData,$H8,f_Name))," ","^",LEN(TRIM(INDEX(FormData,$H8,f_Name)))-LEN(SUBSTITUTE(TRIM(INDEX(FormData,$H8,f_Name))," ",""))))+1,1),"")),"")) | E8: =IF($H8="","",IFERROR(INDEX(EvID,MATCH(INDEX(FormData,$H8,f_Event),EvID,0)),IFERROR(INDEX(EvID,MATCH(INDEX(FormData,$H8,f_Event),EvName,0)),IFERROR(INDEX(EvID,MATCH(INT($C8),EvDate,0)),"(no event that day)")))) | F8: =IF($H8="","",IFERROR(IF(SUMPRODUCT(MAX((WhoKW<>"")*ISNUMBER(SEARCH(WhoKW,INDEX(FormData,$H8,f_Who)&""))*(ROW(WhoKW)-MIN(ROW(WhoKW))+1)))=0,"",INDEX(WhoVal,SUMPRODUCT(MAX((WhoKW<>"")*ISNUMBER(SEARCH(WhoKW,INDEX(FormData,$H8,f_Who)&""))*(ROW(WhoKW)-MIN(ROW(WhoKW))+1))))),"")) | G8: =IF($H8="","",IF(COUNTIF(People!$U$5:$U$604,$B8)+COUNTIF(People!$U$5:$U$604,$B8&"")>0,"✓ logged","→ add")) | H8: =IFERROR(IF(INDEX(FormData,5,f_Id)&""="","",5),"") | I8: =IF($H8="","",IFERROR(INDEX(FormData,$H8,f_Need)&"",""))
A9: 5 | B9: =IF($H9="","",INDEX(FormData,$H9,f_Id)) | C9: =IF($H9="","",IFERROR(INDEX(FormData,$H9,f_Time),"")) | D9: =IF($H9="","",IFERROR(UPPER(LEFT(TRIM(INDEX(FormData,$H9,f_Name)),1)&IFERROR(MID(TRIM(INDEX(FormData,$H9,f_Name)),FIND("^",SUBSTITUTE(TRIM(INDEX(FormData,$H9,f_Name))," ","^",LEN(TRIM(INDEX(FormData,$H9,f_Name)))-LEN(SUBSTITUTE(TRIM(INDEX(FormData,$H9,f_Name))," ",""))))+1,1),"")),"")) | E9: =IF($H9="","",IFERROR(INDEX(EvID,MATCH(INDEX(FormData,$H9,f_Event),EvID,0)),IFERROR(INDEX(EvID,MATCH(INDEX(FormData,$H9,f_Event),EvName,0)),IFERROR(INDEX(EvID,MATCH(INT($C9),EvDate,0)),"(no event that day)")))) | F9: =IF($H9="","",IFERROR(IF(SUMPRODUCT(MAX((WhoKW<>"")*ISNUMBER(SEARCH(WhoKW,INDEX(FormData,$H9,f_Who)&""))*(ROW(WhoKW)-MIN(ROW(WhoKW))+1)))=0,"",INDEX(WhoVal,SUMPRODUCT(MAX((WhoKW<>"")*ISNUMBER(SEARCH(WhoKW,INDEX(FormData,$H9,f_Who)&""))*(ROW(WhoKW)-MIN(ROW(WhoKW))+1))))),"")) | G9: =IF($H9="","",IF(COUNTIF(People!$U$5:$U$604,$B9)+COUNTIF(People!$U$5:$U$604,$B9&"")>0,"✓ logged","→ add")) | H9: =IFERROR(IF(INDEX(FormData,6,f_Id)&""="","",6),"") | I9: =IF($H9="","",IFERROR(INDEX(FormData,$H9,f_Need)&"",""))
A10: 6 | B10: =IF($H10="","",INDEX(FormData,$H10,f_Id)) | C10: =IF($H10="","",IFERROR(INDEX(FormData,$H10,f_Time),"")) | D10: =IF($H10="","",IFERROR(UPPER(LEFT(TRIM(INDEX(FormData,$H10,f_Name)),1)&IFERROR(MID(TRIM(INDEX(FormData,$H10,f_Name)),FIND("^",SUBSTITUTE(TRIM(INDEX(FormData,$H10,f_Name))," ","^",LEN(TRIM(INDEX(FormData,$H10,f_Name)))-LEN(SUBSTITUTE(TRIM(INDEX(FormData,$H10,f_Name))," ",""))))+1,1),"")),"")) | E10: =IF($H10="","",IFERROR(INDEX(EvID,MATCH(INDEX(FormData,$H10,f_Event),EvID,0)),IFERROR(INDEX(EvID,MATCH(INDEX(FormData,$H10,f_Event),EvName,0)),IFERROR(INDEX(EvID,MATCH(INT($C10),EvDate,0)),"(no event that day)")))) | F10: =IF($H10="","",IFERROR(IF(SUMPRODUCT(MAX((WhoKW<>"")*ISNUMBER(SEARCH(WhoKW,INDEX(FormData,$H10,f_Who)&""))*(ROW(WhoKW)-MIN(ROW(WhoKW))+1)))=0,"",INDEX(WhoVal,SUMPRODUCT(MAX((WhoKW<>"")*ISNUMBER(SEARCH(WhoKW,INDEX(FormData,$H10,f_Who)&""))*(ROW(WhoKW)-MIN(ROW(WhoKW))+1))))),"")) | G10: =IF($H10="","",IF(COUNTIF(People!$U$5:$U$604,$B10)+COUNTIF(People!$U$5:$U$604,$B10&"")>0,"✓ logged","→ add")) | H10: =IFERROR(IF(INDEX(FormData,7,f_Id)&""="","",7),"") | I10: =IF($H10="","",IFERROR(INDEX(FormData,$H10,f_Need)&"",""))
A11: 7 | B11: =IF($H11="","",INDEX(FormData,$H11,f_Id)) | C11: =IF($H11="","",IFERROR(INDEX(FormData,$H11,f_Time),"")) | D11: =IF($H11="","",IFERROR(UPPER(LEFT(TRIM(INDEX(FormData,$H11,f_Name)),1)&IFERROR(MID(TRIM(INDEX(FormData,$H11,f_Name)),FIND("^",SUBSTITUTE(TRIM(INDEX(FormData,$H11,f_Name))," ","^",LEN(TRIM(INDEX(FormData,$H11,f_Name)))-LEN(SUBSTITUTE(TRIM(INDEX(FormData,$H11,f_Name))," ",""))))+1,1),"")),"")) | E11: =IF($H11="","",IFERROR(INDEX(EvID,MATCH(INDEX(FormData,$H11,f_Event),EvID,0)),IFERROR(INDEX(EvID,MATCH(INDEX(FormData,$H11,f_Event),EvName,0)),IFERROR(INDEX(EvID,MATCH(INT($C11),EvDate,0)),"(no event that day)")))) | F11: =IF($H11="","",IFERROR(IF(SUMPRODUCT(MAX((WhoKW<>"")*ISNUMBER(SEARCH(WhoKW,INDEX(FormData,$H11,f_Who)&""))*(ROW(WhoKW)-MIN(ROW(WhoKW))+1)))=0,"",INDEX(WhoVal,SUMPRODUCT(MAX((WhoKW<>"")*ISNUMBER(SEARCH(WhoKW,INDEX(FormData,$H11,f_Who)&""))*(ROW(WhoKW)-MIN(ROW(WhoKW))+1))))),"")) | G11: =IF($H11="","",IF(COUNTIF(People!$U$5:$U$604,$B11)+COUNTIF(People!$U$5:$U$604,$B11&"")>0,"✓ logged","→ add")) | H11: =IFERROR(IF(INDEX(FormData,8,f_Id)&""="","",8),"") | I11: =IF($H11="","",IFERROR(INDEX(FormData,$H11,f_Need)&"",""))
A12: 8 | B12: =IF($H12="","",INDEX(FormData,$H12,f_Id)) | C12: =IF($H12="","",IFERROR(INDEX(FormData,$H12,f_Time),"")) | D12: =IF($H12="","",IFERROR(UPPER(LEFT(TRIM(INDEX(FormData,$H12,f_Name)),1)&IFERROR(MID(TRIM(INDEX(FormData,$H12,f_Name)),FIND("^",SUBSTITUTE(TRIM(INDEX(FormData,$H12,f_Name))," ","^",LEN(TRIM(INDEX(FormData,$H12,f_Name)))-LEN(SUBSTITUTE(TRIM(INDEX(FormData,$H12,f_Name))," ",""))))+1,1),"")),"")) | E12: =IF($H12="","",IFERROR(INDEX(EvID,MATCH(INDEX(FormData,$H12,f_Event),EvID,0)),IFERROR(INDEX(EvID,MATCH(INDEX(FormData,$H12,f_Event),EvName,0)),IFERROR(INDEX(EvID,MATCH(INT($C12),EvDate,0)),"(no event that day)")))) | F12: =IF($H12="","",IFERROR(IF(SUMPRODUCT(MAX((WhoKW<>"")*ISNUMBER(SEARCH(WhoKW,INDEX(FormData,$H12,f_Who)&""))*(ROW(WhoKW)-MIN(ROW(WhoKW))+1)))=0,"",INDEX(WhoVal,SUMPRODUCT(MAX((WhoKW<>"")*ISNUMBER(SEARCH(WhoKW,INDEX(FormData,$H12,f_Who)&""))*(ROW(WhoKW)-MIN(ROW(WhoKW))+1))))),"")) | G12: =IF($H12="","",IF(COUNTIF(People!$U$5:$U$604,$B12)+COUNTIF(People!$U$5:$U$604,$B12&"")>0,"✓ logged","→ add")) | H12: =IFERROR(IF(INDEX(FormData,9,f_Id)&""="","",9),"") | I12: =IF($H12="","",IFERROR(INDEX(FormData,$H12,f_Need)&"",""))
A13: 9 | B13: =IF($H13="","",INDEX(FormData,$H13,f_Id)) | C13: =IF($H13="","",IFERROR(INDEX(FormData,$H13,f_Time),"")) | D13: =IF($H13="","",IFERROR(UPPER(LEFT(TRIM(INDEX(FormData,$H13,f_Name)),1)&IFERROR(MID(TRIM(INDEX(FormData,$H13,f_Name)),FIND("^",SUBSTITUTE(TRIM(INDEX(FormData,$H13,f_Name))," ","^",LEN(TRIM(INDEX(FormData,$H13,f_Name)))-LEN(SUBSTITUTE(TRIM(INDEX(FormData,$H13,f_Name))," ",""))))+1,1),"")),"")) | E13: =IF($H13="","",IFERROR(INDEX(EvID,MATCH(INDEX(FormData,$H13,f_Event),EvID,0)),IFERROR(INDEX(EvID,MATCH(INDEX(FormData,$H13,f_Event),EvName,0)),IFERROR(INDEX(EvID,MATCH(INT($C13),EvDate,0)),"(no event that day)")))) | F13: =IF($H13="","",IFERROR(IF(SUMPRODUCT(MAX((WhoKW<>"")*ISNUMBER(SEARCH(WhoKW,INDEX(FormData,$H13,f_Who)&""))*(ROW(WhoKW)-MIN(ROW(WhoKW))+1)))=0,"",INDEX(WhoVal,SUMPRODUCT(MAX((WhoKW<>"")*ISNUMBER(SEARCH(WhoKW,INDEX(FormData,$H13,f_Who)&""))*(ROW(WhoKW)-MIN(ROW(WhoKW))+1))))),"")) | G13: =IF($H13="","",IF(COUNTIF(People!$U$5:$U$604,$B13)+COUNTIF(People!$U$5:$U$604,$B13&"")>0,"✓ logged","→ add")) | H13: =IFERROR(IF(INDEX(FormData,10,f_Id)&""="","",10),"") | I13: =IF($H13="","",IFERROR(INDEX(FormData,$H13,f_Need)&"",""))
A14: 10 | B14: =IF($H14="","",INDEX(FormData,$H14,f_Id)) | C14: =IF($H14="","",IFERROR(INDEX(FormData,$H14,f_Time),"")) | D14: =IF($H14="","",IFERROR(UPPER(LEFT(TRIM(INDEX(FormData,$H14,f_Name)),1)&IFERROR(MID(TRIM(INDEX(FormData,$H14,f_Name)),FIND("^",SUBSTITUTE(TRIM(INDEX(FormData,$H14,f_Name))," ","^",LEN(TRIM(INDEX(FormData,$H14,f_Name)))-LEN(SUBSTITUTE(TRIM(INDEX(FormData,$H14,f_Name))," ",""))))+1,1),"")),"")) | E14: =IF($H14="","",IFERROR(INDEX(EvID,MATCH(INDEX(FormData,$H14,f_Event),EvID,0)),IFERROR(INDEX(EvID,MATCH(INDEX(FormData,$H14,f_Event),EvName,0)),IFERROR(INDEX(EvID,MATCH(INT($C14),EvDate,0)),"(no event that day)")))) | F14: =IF($H14="","",IFERROR(IF(SUMPRODUCT(MAX((WhoKW<>"")*ISNUMBER(SEARCH(WhoKW,INDEX(FormData,$H14,f_Who)&""))*(ROW(WhoKW)-MIN(ROW(WhoKW))+1)))=0,"",INDEX(WhoVal,SUMPRODUCT(MAX((WhoKW<>"")*ISNUMBER(SEARCH(WhoKW,INDEX(FormData,$H14,f_Who)&""))*(ROW(WhoKW)-MIN(ROW(WhoKW))+1))))),"")) | G14: =IF($H14="","",IF(COUNTIF(People!$U$5:$U$604,$B14)+COUNTIF(People!$U$5:$U$604,$B14&"")>0,"✓ logged","→ add")) | H14: =IFERROR(IF(INDEX(FormData,11,f_Id)&""="","",11),"") | I14: =IF($H14="","",IFERROR(INDEX(FormData,$H14,f_Need)&"",""))
A15: 11 | B15: =IF($H15="","",INDEX(FormData,$H15,f_Id)) | C15: =IF($H15="","",IFERROR(INDEX(FormData,$H15,f_Time),"")) | D15: =IF($H15="","",IFERROR(UPPER(LEFT(TRIM(INDEX(FormData,$H15,f_Name)),1)&IFERROR(MID(TRIM(INDEX(FormData,$H15,f_Name)),FIND("^",SUBSTITUTE(TRIM(INDEX(FormData,$H15,f_Name))," ","^",LEN(TRIM(INDEX(FormData,$H15,f_Name)))-LEN(SUBSTITUTE(TRIM(INDEX(FormData,$H15,f_Name))," ",""))))+1,1),"")),"")) | E15: =IF($H15="","",IFERROR(INDEX(EvID,MATCH(INDEX(FormData,$H15,f_Event),EvID,0)),IFERROR(INDEX(EvID,MATCH(INDEX(FormData,$H15,f_Event),EvName,0)),IFERROR(INDEX(EvID,MATCH(INT($C15),EvDate,0)),"(no event that day)")))) | F15: =IF($H15="","",IFERROR(IF(SUMPRODUCT(MAX((WhoKW<>"")*ISNUMBER(SEARCH(WhoKW,INDEX(FormData,$H15,f_Who)&""))*(ROW(WhoKW)-MIN(ROW(WhoKW))+1)))=0,"",INDEX(WhoVal,SUMPRODUCT(MAX((WhoKW<>"")*ISNUMBER(SEARCH(WhoKW,INDEX(FormData,$H15,f_Who)&""))*(ROW(WhoKW)-MIN(ROW(WhoKW))+1))))),"")) | G15: =IF($H15="","",IF(COUNTIF(People!$U$5:$U$604,$B15)+COUNTIF(People!$U$5:$U$604,$B15&"")>0,"✓ logged","→ add")) | H15: =IFERROR(IF(INDEX(FormData,12,f_Id)&""="","",12),"") | I15: =IF($H15="","",IFERROR(INDEX(FormData,$H15,f_Need)&"",""))
A16: 12 | B16: =IF($H16="","",INDEX(FormData,$H16,f_Id)) | C16: =IF($H16="","",IFERROR(INDEX(FormData,$H16,f_Time),"")) | D16: =IF($H16="","",IFERROR(UPPER(LEFT(TRIM(INDEX(FormData,$H16,f_Name)),1)&IFERROR(MID(TRIM(INDEX(FormData,$H16,f_Name)),FIND("^",SUBSTITUTE(TRIM(INDEX(FormData,$H16,f_Name))," ","^",LEN(TRIM(INDEX(FormData,$H16,f_Name)))-LEN(SUBSTITUTE(TRIM(INDEX(FormData,$H16,f_Name))," ",""))))+1,1),"")),"")) | E16: =IF($H16="","",IFERROR(INDEX(EvID,MATCH(INDEX(FormData,$H16,f_Event),EvID,0)),IFERROR(INDEX(EvID,MATCH(INDEX(FormData,$H16,f_Event),EvName,0)),IFERROR(INDEX(EvID,MATCH(INT($C16),EvDate,0)),"(no event that day)")))) | F16: =IF($H16="","",IFERROR(IF(SUMPRODUCT(MAX((WhoKW<>"")*ISNUMBER(SEARCH(WhoKW,INDEX(FormData,$H16,f_Who)&""))*(ROW(WhoKW)-MIN(ROW(WhoKW))+1)))=0,"",INDEX(WhoVal,SUMPRODUCT(MAX((WhoKW<>"")*ISNUMBER(SEARCH(WhoKW,INDEX(FormData,$H16,f_Who)&""))*(ROW(WhoKW)-MIN(ROW(WhoKW))+1))))),"")) | G16: =IF($H16="","",IF(COUNTIF(People!$U$5:$U$604,$B16)+COUNTIF(People!$U$5:$U$604,$B16&"")>0,"✓ logged","→ add")) | H16: =IFERROR(IF(INDEX(FormData,13,f_Id)&""="","",13),"") | I16: =IF($H16="","",IFERROR(INDEX(FormData,$H16,f_Need)&"",""))
A17: 13 | B17: =IF($H17="","",INDEX(FormData,$H17,f_Id)) | C17: =IF($H17="","",IFERROR(INDEX(FormData,$H17,f_Time),"")) | D17: =IF($H17="","",IFERROR(UPPER(LEFT(TRIM(INDEX(FormData,$H17,f_Name)),1)&IFERROR(MID(TRIM(INDEX(FormData,$H17,f_Name)),FIND("^",SUBSTITUTE(TRIM(INDEX(FormData,$H17,f_Name))," ","^",LEN(TRIM(INDEX(FormData,$H17,f_Name)))-LEN(SUBSTITUTE(TRIM(INDEX(FormData,$H17,f_Name))," ",""))))+1,1),"")),"")) | E17: =IF($H17="","",IFERROR(INDEX(EvID,MATCH(INDEX(FormData,$H17,f_Event),EvID,0)),IFERROR(INDEX(EvID,MATCH(INDEX(FormData,$H17,f_Event),EvName,0)),IFERROR(INDEX(EvID,MATCH(INT($C17),EvDate,0)),"(no event that day)")))) | F17: =IF($H17="","",IFERROR(IF(SUMPRODUCT(MAX((WhoKW<>"")*ISNUMBER(SEARCH(WhoKW,INDEX(FormData,$H17,f_Who)&""))*(ROW(WhoKW)-MIN(ROW(WhoKW))+1)))=0,"",INDEX(WhoVal,SUMPRODUCT(MAX((WhoKW<>"")*ISNUMBER(SEARCH(WhoKW,INDEX(FormData,$H17,f_Who)&""))*(ROW(WhoKW)-MIN(ROW(WhoKW))+1))))),"")) | G17: =IF($H17="","",IF(COUNTIF(People!$U$5:$U$604,$B17)+COUNTIF(People!$U$5:$U$604,$B17&"")>0,"✓ logged","→ add")) | H17: =IFERROR(IF(INDEX(FormData,14,f_Id)&""="","",14),"") | I17: =IF($H17="","",IFERROR(INDEX(FormData,$H17,f_Need)&"",""))
A18: 14 | B18: =IF($H18="","",INDEX(FormData,$H18,f_Id)) | C18: =IF($H18="","",IFERROR(INDEX(FormData,$H18,f_Time),"")) | D18: =IF($H18="","",IFERROR(UPPER(LEFT(TRIM(INDEX(FormData,$H18,f_Name)),1)&IFERROR(MID(TRIM(INDEX(FormData,$H18,f_Name)),FIND("^",SUBSTITUTE(TRIM(INDEX(FormData,$H18,f_Name))," ","^",LEN(TRIM(INDEX(FormData,$H18,f_Name)))-LEN(SUBSTITUTE(TRIM(INDEX(FormData,$H18,f_Name))," ",""))))+1,1),"")),"")) | E18: =IF($H18="","",IFERROR(INDEX(EvID,MATCH(INDEX(FormData,$H18,f_Event),EvID,0)),IFERROR(INDEX(EvID,MATCH(INDEX(FormData,$H18,f_Event),EvName,0)),IFERROR(INDEX(EvID,MATCH(INT($C18),EvDate,0)),"(no event that day)")))) | F18: =IF($H18="","",IFERROR(IF(SUMPRODUCT(MAX((WhoKW<>"")*ISNUMBER(SEARCH(WhoKW,INDEX(FormData,$H18,f_Who)&""))*(ROW(WhoKW)-MIN(ROW(WhoKW))+1)))=0,"",INDEX(WhoVal,SUMPRODUCT(MAX((WhoKW<>"")*ISNUMBER(SEARCH(WhoKW,INDEX(FormData,$H18,f_Who)&""))*(ROW(WhoKW)-MIN(ROW(WhoKW))+1))))),"")) | G18: =IF($H18="","",IF(COUNTIF(People!$U$5:$U$604,$B18)+COUNTIF(People!$U$5:$U$604,$B18&"")>0,"✓ logged","→ add")) | H18: =IFERROR(IF(INDEX(FormData,15,f_Id)&""="","",15),"") | I18: =IF($H18="","",IFERROR(INDEX(FormData,$H18,f_Need)&"",""))
A19: 15 | B19: =IF($H19="","",INDEX(FormData,$H19,f_Id)) | C19: =IF($H19="","",IFERROR(INDEX(FormData,$H19,f_Time),"")) | D19: =IF($H19="","",IFERROR(UPPER(LEFT(TRIM(INDEX(FormData,$H19,f_Name)),1)&IFERROR(MID(TRIM(INDEX(FormData,$H19,f_Name)),FIND("^",SUBSTITUTE(TRIM(INDEX(FormData,$H19,f_Name))," ","^",LEN(TRIM(INDEX(FormData,$H19,f_Name)))-LEN(SUBSTITUTE(TRIM(INDEX(FormData,$H19,f_Name))," ",""))))+1,1),"")),"")) | E19: =IF($H19="","",IFERROR(INDEX(EvID,MATCH(INDEX(FormData,$H19,f_Event),EvID,0)),IFERROR(INDEX(EvID,MATCH(INDEX(FormData,$H19,f_Event),EvName,0)),IFERROR(INDEX(EvID,MATCH(INT($C19),EvDate,0)),"(no event that day)")))) | F19: =IF($H19="","",IFERROR(IF(SUMPRODUCT(MAX((WhoKW<>"")*ISNUMBER(SEARCH(WhoKW,INDEX(FormData,$H19,f_Who)&""))*(ROW(WhoKW)-MIN(ROW(WhoKW))+1)))=0,"",INDEX(WhoVal,SUMPRODUCT(MAX((WhoKW<>"")*ISNUMBER(SEARCH(WhoKW,INDEX(FormData,$H19,f_Who)&""))*(ROW(WhoKW)-MIN(ROW(WhoKW))+1))))),"")) | G19: =IF($H19="","",IF(COUNTIF(People!$U$5:$U$604,$B19)+COUNTIF(People!$U$5:$U$604,$B19&"")>0,"✓ logged","→ add")) | H19: =IFERROR(IF(INDEX(FormData,16,f_Id)&""="","",16),"") | I19: =IF($H19="","",IFERROR(INDEX(FormData,$H19,f_Need)&"",""))
A20: 16 | B20: =IF($H20="","",INDEX(FormData,$H20,f_Id)) | C20: =IF($H20="","",IFERROR(INDEX(FormData,$H20,f_Time),"")) | D20: =IF($H20="","",IFERROR(UPPER(LEFT(TRIM(INDEX(FormData,$H20,f_Name)),1)&IFERROR(MID(TRIM(INDEX(FormData,$H20,f_Name)),FIND("^",SUBSTITUTE(TRIM(INDEX(FormData,$H20,f_Name))," ","^",LEN(TRIM(INDEX(FormData,$H20,f_Name)))-LEN(SUBSTITUTE(TRIM(INDEX(FormData,$H20,f_Name))," ",""))))+1,1),"")),"")) | E20: =IF($H20="","",IFERROR(INDEX(EvID,MATCH(INDEX(FormData,$H20,f_Event),EvID,0)),IFERROR(INDEX(EvID,MATCH(INDEX(FormData,$H20,f_Event),EvName,0)),IFERROR(INDEX(EvID,MATCH(INT($C20),EvDate,0)),"(no event that day)")))) | F20: =IF($H20="","",IFERROR(IF(SUMPRODUCT(MAX((WhoKW<>"")*ISNUMBER(SEARCH(WhoKW,INDEX(FormData,$H20,f_Who)&""))*(ROW(WhoKW)-MIN(ROW(WhoKW))+1)))=0,"",INDEX(WhoVal,SUMPRODUCT(MAX((WhoKW<>"")*ISNUMBER(SEARCH(WhoKW,INDEX(FormData,$H20,f_Who)&""))*(ROW(WhoKW)-MIN(ROW(WhoKW))+1))))),"")) | G20: =IF($H20="","",IF(COUNTIF(People!$U$5:$U$604,$B20)+COUNTIF(People!$U$5:$U$604,$B20&"")>0,"✓ logged","→ add")) | H20: =IFERROR(IF(INDEX(FormData,17,f_Id)&""="","",17),"") | I20: =IF($H20="","",IFERROR(INDEX(FormData,$H20,f_Need)&"",""))
A21: 17 | B21: =IF($H21="","",INDEX(FormData,$H21,f_Id)) | C21: =IF($H21="","",IFERROR(INDEX(FormData,$H21,f_Time),"")) | D21: =IF($H21="","",IFERROR(UPPER(LEFT(TRIM(INDEX(FormData,$H21,f_Name)),1)&IFERROR(MID(TRIM(INDEX(FormData,$H21,f_Name)),FIND("^",SUBSTITUTE(TRIM(INDEX(FormData,$H21,f_Name))," ","^",LEN(TRIM(INDEX(FormData,$H21,f_Name)))-LEN(SUBSTITUTE(TRIM(INDEX(FormData,$H21,f_Name))," ",""))))+1,1),"")),"")) | E21: =IF($H21="","",IFERROR(INDEX(EvID,MATCH(INDEX(FormData,$H21,f_Event),EvID,0)),IFERROR(INDEX(EvID,MATCH(INDEX(FormData,$H21,f_Event),EvName,0)),IFERROR(INDEX(EvID,MATCH(INT($C21),EvDate,0)),"(no event that day)")))) | F21: =IF($H21="","",IFERROR(IF(SUMPRODUCT(MAX((WhoKW<>"")*ISNUMBER(SEARCH(WhoKW,INDEX(FormData,$H21,f_Who)&""))*(ROW(WhoKW)-MIN(ROW(WhoKW))+1)))=0,"",INDEX(WhoVal,SUMPRODUCT(MAX((WhoKW<>"")*ISNUMBER(SEARCH(WhoKW,INDEX(FormData,$H21,f_Who)&""))*(ROW(WhoKW)-MIN(ROW(WhoKW))+1))))),"")) | G21: =IF($H21="","",IF(COUNTIF(People!$U$5:$U$604,$B21)+COUNTIF(People!$U$5:$U$604,$B21&"")>0,"✓ logged","→ add")) | H21: =IFERROR(IF(INDEX(FormData,18,f_Id)&""="","",18),"") | I21: =IF($H21="","",IFERROR(INDEX(FormData,$H21,f_Need)&"",""))
A22: 18 | B22: =IF($H22="","",INDEX(FormData,$H22,f_Id)) | C22: =IF($H22="","",IFERROR(INDEX(FormData,$H22,f_Time),"")) | D22: =IF($H22="","",IFERROR(UPPER(LEFT(TRIM(INDEX(FormData,$H22,f_Name)),1)&IFERROR(MID(TRIM(INDEX(FormData,$H22,f_Name)),FIND("^",SUBSTITUTE(TRIM(INDEX(FormData,$H22,f_Name))," ","^",LEN(TRIM(INDEX(FormData,$H22,f_Name)))-LEN(SUBSTITUTE(TRIM(INDEX(FormData,$H22,f_Name))," ",""))))+1,1),"")),"")) | E22: =IF($H22="","",IFERROR(INDEX(EvID,MATCH(INDEX(FormData,$H22,f_Event),EvID,0)),IFERROR(INDEX(EvID,MATCH(INDEX(FormData,$H22,f_Event),EvName,0)),IFERROR(INDEX(EvID,MATCH(INT($C22),EvDate,0)),"(no event that day)")))) | F22: =IF($H22="","",IFERROR(IF(SUMPRODUCT(MAX((WhoKW<>"")*ISNUMBER(SEARCH(WhoKW,INDEX(FormData,$H22,f_Who)&""))*(ROW(WhoKW)-MIN(ROW(WhoKW))+1)))=0,"",INDEX(WhoVal,SUMPRODUCT(MAX((WhoKW<>"")*ISNUMBER(SEARCH(WhoKW,INDEX(FormData,$H22,f_Who)&""))*(ROW(WhoKW)-MIN(ROW(WhoKW))+1))))),"")) | G22: =IF($H22="","",IF(COUNTIF(People!$U$5:$U$604,$B22)+COUNTIF(People!$U$5:$U$604,$B22&"")>0,"✓ logged","→ add")) | H22: =IFERROR(IF(INDEX(FormData,19,f_Id)&""="","",19),"") | I22: =IF($H22="","",IFERROR(INDEX(FormData,$H22,f_Need)&"",""))
A23: 19 | B23: =IF($H23="","",INDEX(FormData,$H23,f_Id)) | C23: =IF($H23="","",IFERROR(INDEX(FormData,$H23,f_Time),"")) | D23: =IF($H23="","",IFERROR(UPPER(LEFT(TRIM(INDEX(FormData,$H23,f_Name)),1)&IFERROR(MID(TRIM(INDEX(FormData,$H23,f_Name)),FIND("^",SUBSTITUTE(TRIM(INDEX(FormData,$H23,f_Name))," ","^",LEN(TRIM(INDEX(FormData,$H23,f_Name)))-LEN(SUBSTITUTE(TRIM(INDEX(FormData,$H23,f_Name))," ",""))))+1,1),"")),"")) | E23: =IF($H23="","",IFERROR(INDEX(EvID,MATCH(INDEX(FormData,$H23,f_Event),EvID,0)),IFERROR(INDEX(EvID,MATCH(INDEX(FormData,$H23,f_Event),EvName,0)),IFERROR(INDEX(EvID,MATCH(INT($C23),EvDate,0)),"(no event that day)")))) | F23: =IF($H23="","",IFERROR(IF(SUMPRODUCT(MAX((WhoKW<>"")*ISNUMBER(SEARCH(WhoKW,INDEX(FormData,$H23,f_Who)&""))*(ROW(WhoKW)-MIN(ROW(WhoKW))+1)))=0,"",INDEX(WhoVal,SUMPRODUCT(MAX((WhoKW<>"")*ISNUMBER(SEARCH(WhoKW,INDEX(FormData,$H23,f_Who)&""))*(ROW(WhoKW)-MIN(ROW(WhoKW))+1))))),"")) | G23: =IF($H23="","",IF(COUNTIF(People!$U$5:$U$604,$B23)+COUNTIF(People!$U$5:$U$604,$B23&"")>0,"✓ logged","→ add")) | H23: =IFERROR(IF(INDEX(FormData,20,f_Id)&""="","",20),"") | I23: =IF($H23="","",IFERROR(INDEX(FormData,$H23,f_Need)&"",""))
A24: 20 | B24: =IF($H24="","",INDEX(FormData,$H24,f_Id)) | C24: =IF($H24="","",IFERROR(INDEX(FormData,$H24,f_Time),"")) | D24: =IF($H24="","",IFERROR(UPPER(LEFT(TRIM(INDEX(FormData,$H24,f_Name)),1)&IFERROR(MID(TRIM(INDEX(FormData,$H24,f_Name)),FIND("^",SUBSTITUTE(TRIM(INDEX(FormData,$H24,f_Name))," ","^",LEN(TRIM(INDEX(FormData,$H24,f_Name)))-LEN(SUBSTITUTE(TRIM(INDEX(FormData,$H24,f_Name))," ",""))))+1,1),"")),"")) | E24: =IF($H24="","",IFERROR(INDEX(EvID,MATCH(INDEX(FormData,$H24,f_Event),EvID,0)),IFERROR(INDEX(EvID,MATCH(INDEX(FormData,$H24,f_Event),EvName,0)),IFERROR(INDEX(EvID,MATCH(INT($C24),EvDate,0)),"(no event that day)")))) | F24: =IF($H24="","",IFERROR(IF(SUMPRODUCT(MAX((WhoKW<>"")*ISNUMBER(SEARCH(WhoKW,INDEX(FormData,$H24,f_Who)&""))*(ROW(WhoKW)-MIN(ROW(WhoKW))+1)))=0,"",INDEX(WhoVal,SUMPRODUCT(MAX((WhoKW<>"")*ISNUMBER(SEARCH(WhoKW,INDEX(FormData,$H24,f_Who)&""))*(ROW(WhoKW)-MIN(ROW(WhoKW))+1))))),"")) | G24: =IF($H24="","",IF(COUNTIF(People!$U$5:$U$604,$B24)+COUNTIF(People!$U$5:$U$604,$B24&"")>0,"✓ logged","→ add")) | H24: =IFERROR(IF(INDEX(FormData,21,f_Id)&""="","",21),"") | I24: =IF($H24="","",IFERROR(INDEX(FormData,$H24,f_Need)&"",""))
A25: 21 | B25: =IF($H25="","",INDEX(FormData,$H25,f_Id)) | C25: =IF($H25="","",IFERROR(INDEX(FormData,$H25,f_Time),"")) | D25: =IF($H25="","",IFERROR(UPPER(LEFT(TRIM(INDEX(FormData,$H25,f_Name)),1)&IFERROR(MID(TRIM(INDEX(FormData,$H25,f_Name)),FIND("^",SUBSTITUTE(TRIM(INDEX(FormData,$H25,f_Name))," ","^",LEN(TRIM(INDEX(FormData,$H25,f_Name)))-LEN(SUBSTITUTE(TRIM(INDEX(FormData,$H25,f_Name))," ",""))))+1,1),"")),"")) | E25: =IF($H25="","",IFERROR(INDEX(EvID,MATCH(INDEX(FormData,$H25,f_Event),EvID,0)),IFERROR(INDEX(EvID,MATCH(INDEX(FormData,$H25,f_Event),EvName,0)),IFERROR(INDEX(EvID,MATCH(INT($C25),EvDate,0)),"(no event that day)")))) | F25: =IF($H25="","",IFERROR(IF(SUMPRODUCT(MAX((WhoKW<>"")*ISNUMBER(SEARCH(WhoKW,INDEX(FormData,$H25,f_Who)&""))*(ROW(WhoKW)-MIN(ROW(WhoKW))+1)))=0,"",INDEX(WhoVal,SUMPRODUCT(MAX((WhoKW<>"")*ISNUMBER(SEARCH(WhoKW,INDEX(FormData,$H25,f_Who)&""))*(ROW(WhoKW)-MIN(ROW(WhoKW))+1))))),"")) | G25: =IF($H25="","",IF(COUNTIF(People!$U$5:$U$604,$B25)+COUNTIF(People!$U$5:$U$604,$B25&"")>0,"✓ logged","→ add")) | H25: =IFERROR(IF(INDEX(FormData,22,f_Id)&""="","",22),"") | I25: =IF($H25="","",IFERROR(INDEX(FormData,$H25,f_Need)&"",""))
